<mujoco model="a1">
    <compiler angle="radian" meshdir="meshes/" coordinate="local" />
    <size njmax="500" nconmax="100" />
    <default>
        <joint limited="false" armature="0.01"/>>
        <geom contype="1" conaffinity="0" condim="3" margin="0.001" solref=".02 1" solimp=".8 .8 .01"/>
    </default>
    <asset>
        <mesh name="trunk" file="trunk.stl" />
        <mesh name="hip" file="hip.stl" />
        <mesh name="thigh_mirror" file="thigh_mirror.stl" />
        <mesh name="calf" file="calf.stl" />
        <mesh name="thigh" file="thigh.stl" />
        <texture builtin="flat" height="1278" mark="cross" markrgb="1 1 1" name="texgeom" random="0.01" rgb1="0.8 0.6 0.4" rgb2="0.8 0.6 0.4" type="cube" width="127"/>
        <texture builtin="checker" height="100" name="texplane" rgb1="0 0 0" rgb2="0.8 0.8 0.8" type="2d" width="100"/>
        <material name="MatPlane" reflectance="0.5" shininess="1" specular="1" texrepeat="60 60" texture="texplane"/>
        <material name="geom" texture="texgeom" texuniform="true"/>
        <texture type="skybox" builtin="gradient" rgb1="0.3 0.5 0.7" rgb2="0 0 0" width="512" height="512"/>
    </asset>
    <option timestep="0.0002" iterations="50" solver="PGS" gravity="0 0 -9.81">
        <flag energy="enable" gravity="enable"/>
    </option>
    <worldbody>
        <geom conaffinity="1" condim="3" friction = "1 0.5 0.5" material="MatPlane" name="floor" pos="0 0 -0.5" rgba="0.8 0.9 0.8 1" size="40 40 40" type="plane"/>
        <light directional="true" diffuse=".8 .8 .8" specular=".2 .2 .2" pos="0 0 0.5" dir="0 0 -1"/>
        <body name="Body" pos="0 0 0" euler="0 0 0">
            <inertial pos="0.012731 0.002186 0.000515" mass="4.713" 
                fullinertia="1.62642913929261E-06 2.16302130147651E-06 2.57241198744282E-06 -2.15537782337987E-07 -2.3575284377688E-08 -1.07181784470334E-08"/>
            <joint type="free" name="free"/>
            <geom size="0.0005 0.0005 0.0005" type="box" contype="0" conaffinity="0" group="1" />
            <geom type="mesh" contype="0" conaffinity="0" group="1" rgba="1 0.423529 0.0392157 1" mesh="trunk" />
            <geom size="0.1335 0.097 0.057" type="box" rgba="1 0.423529 0.0392157 0" />
            <geom size="0.0005 0.0005 0.0005" type="box" contype="0" conaffinity="0" group="1" rgba="0.8 0 0 0" />
            <geom size="0.0005 0.0005 0.0005" type="box" rgba="0.8 0 0 0" />
            <body name="FR_hip" pos="0.183 -0.047 0">
                <inertial pos="-0.003311 -0.000635 3.1e-05" quat="0.507528 0.506268 0.491507 0.494499" mass="0.696" diaginertia="0.000807752 0.00055293 0.000468983" />
                <joint name="FR_hip_joint" pos="0 0 0" axis="1 0 0" limited="true" range="-0.1 0.1" /> <!-- 0.802851 -->
                <geom quat="0 1 0 0" type="mesh" contype="0" conaffinity="0" group="1" rgba="1 0.423529 0.0392157 1" mesh="hip" />
                <geom size="0.046 0.02" quat="0.707107 0.707107 0 0" type="cylinder" rgba="1 0.423529 0.0392157 0" />
                <body name="FR_thigh" pos="0 -0.08505 0">
                    <inertial pos="-0.003237 0.022327 -0.027326" quat="0.999125 -0.00256393 -0.0409531 -0.00806091" mass="1.013" diaginertia="0.00555739 0.00513936 0.00133944" />
                    <joint name="FR_thigh_joint" pos="0 0 0" axis="0 1 0" limited="true" range="-1.0472 4.18879" />
                    <geom type="mesh" contype="0" conaffinity="0" group="1" rgba="1 0.423529 0.0392157 1" mesh="thigh_mirror" />
                    <geom size="0.1 0.01225 0.017" pos="0 0 -0.1" quat="0.707107 0 0.707107 0" type="box" rgba="1 0.423529 0.0392157 0" />
                    <body name="FR_calf" pos="0 0 -0.2">
                        <inertial pos="0.00472659 0 -0.131975" quat="0.706886 0.017653 0.017653 0.706886" mass="0.226" diaginertia="0.00340344 0.00339393 3.54834e-05" />
                        <joint name="FR_calf_joint" pos="0 0 0" axis="0 1 0" limited="true" range="-2.69653 -0.916298" />
                        <geom type="mesh" contype="0" conaffinity="0" group="1" rgba="1 0.423529 0.0392157 1" mesh="calf" />
                        <geom size="0.1 0.008 0.008" pos="0 0 -0.1" quat="0.707107 0 0.707107 0" type="box" rgba="1 0.423529 0.0392157 0" />
                        <geom size="0.01" pos="0 0 -0.2" contype="0" conaffinity="0" group="1" rgba="1 0.423529 0.0392157 1" />
                        <geom size="0.02" pos="0 0 -0.2" rgba="1 0.423529 0.0392157 0" />
                    </body>
                </body>
            </body>
            <body name="FL_hip" pos="0.183 0.047 0">
                <inertial pos="-0.003311 0.000635 3.1e-05" quat="0.494499 0.491507 0.506268 0.507528" mass="0.696" diaginertia="0.000807752 0.00055293 0.000468983" />
                <joint name="FL_hip_joint" pos="0 0 0" axis="1 0 0" limited="true" range="-0.1 0.1" />
                <geom type="mesh" contype="0" conaffinity="0" group="1" rgba="1 0.423529 0.0392157 1" mesh="hip" />
                <geom size="0.046 0.02" quat="0.707107 0.707107 0 0" type="cylinder" rgba="1 0.423529 0.0392157 0" />
                <body name="FL_thigh" pos="0 0.08505 0">
                    <inertial pos="-0.003237 -0.022327 -0.027326" quat="0.999125 0.00256393 -0.0409531 0.00806091" mass="1.013" diaginertia="0.00555739 0.00513936 0.00133944" />
                    <joint name="FL_thigh_joint" pos="0 0 0" axis="0 1 0" limited="true" range="-1.0472 4.18879" />
                    <geom type="mesh" contype="0" conaffinity="0" group="1" rgba="1 0.423529 0.0392157 1" mesh="thigh" />
                    <geom size="0.1 0.01225 0.017" pos="0 0 -0.1" quat="0.707107 0 0.707107 0" type="box" rgba="1 0.423529 0.0392157 0" />
                    <body name="FL_calf" pos="0 0 -0.2">
                        <inertial pos="0.00472659 0 -0.131975" quat="0.706886 0.017653 0.017653 0.706886" mass="0.226" diaginertia="0.00340344 0.00339393 3.54834e-05" />
                        <joint name="FL_calf_joint" pos="0 0 0" axis="0 1 0" limited="true" range="-2.69653 -0.916298" />
                        <geom type="mesh" contype="0" conaffinity="0" group="1" rgba="1 0.423529 0.0392157 1" mesh="calf" />
                        <geom size="0.1 0.008 0.008" pos="0 0 -0.1" quat="0.707107 0 0.707107 0" type="box" rgba="1 0.423529 0.0392157 0" />
                        <geom size="0.01" pos="0 0 -0.2" contype="0" conaffinity="0" group="1" rgba="1 0.423529 0.0392157 0" />
                        <geom size="0.02" pos="0 0 -0.2" rgba="1 0.423529 0.0392157 0" />
                    </body>
                </body>
            </body>
            <body name="RR_hip" pos="-0.183 -0.047 0">
                <inertial pos="0.003311 -0.000635 3.1e-05" quat="0.491507 0.494499 0.507528 0.506268" mass="0.696" diaginertia="0.000807752 0.00055293 0.000468983" />
                <joint name="RR_hip_joint" pos="0 0 0" axis="1 0 0" limited="true" range="-0.1 0.1" />
                <geom quat="0 0 0 -1" type="mesh" contype="0" conaffinity="0" group="1" rgba="1 0.423529 0.0392157 1" mesh="hip" />
                <geom size="0.046 0.02" quat="0.707107 0.707107 0 0" type="cylinder" rgba="1 0.423529 0.0392157 0" />
                <body name="RR_thigh" pos="0 -0.08505 0">
                    <inertial pos="-0.003237 0.022327 -0.027326" quat="0.999125 -0.00256393 -0.0409531 -0.00806091" mass="1.013" diaginertia="0.00555739 0.00513936 0.00133944" />
                    <joint name="RR_thigh_joint" pos="0 0 0" axis="0 1 0" limited="true" range="-1.0472 4.18879" />
                    <geom type="mesh" contype="0" conaffinity="0" group="1" rgba="1 0.423529 0.0392157 1" mesh="thigh_mirror" />
                    <geom size="0.1 0.01225 0.017" pos="0 0 -0.1" quat="0.707107 0 0.707107 0" type="box" rgba="1 0.423529 0.0392157 0" />
                    <body name="RR_calf" pos="0 0 -0.2">
                        <inertial pos="0.00472659 0 -0.131975" quat="0.706886 0.017653 0.017653 0.706886" mass="0.226" diaginertia="0.00340344 0.00339393 3.54834e-05" />
                        <joint name="RR_calf_joint" pos="0 0 0" axis="0 1 0" limited="true" range="-2.69653 -0.916298" />
                        <geom type="mesh" contype="0" conaffinity="0" group="1" rgba="1 0.423529 0.0392157 1" mesh="calf" />
                        <geom size="0.1 0.008 0.008" pos="0 0 -0.1" quat="0.707107 0 0.707107 0" type="box" rgba="1 0.423529 0.0392157 0" />
                        <geom size="0.01" pos="0 0 -0.2" contype="0" conaffinity="0" group="1" rgba="1 0.423529 0.0392157 0" />
                        <geom size="0.02" pos="0 0 -0.2" rgba="1 0.423529 0.0392157 0" />
                    </body>
                </body>
            </body>
            <body name="RL_hip" pos="-0.183 0.047 0">
                <inertial pos="0.003311 0.000635 3.1e-05" quat="0.506268 0.507528 0.494499 0.491507" mass="0.696" diaginertia="0.000807752 0.00055293 0.000468983" />
                <joint name="RL_hip_joint" pos="0 0 0" axis="1 0 0" limited="true" range="-0.1 0.1" />
                <geom quat="0 0 1 0" type="mesh" contype="0" conaffinity="0" group="1" rgba="1 0.423529 0.0392157 1" mesh="hip" />
                <geom size="0.046 0.02" quat="0.707107 0.707107 0 0" type="cylinder" rgba="1 0.423529 0.0392157 0" />
                <body name="RL_thigh" pos="0 0.08505 0">
                    <inertial pos="-0.003237 -0.022327 -0.027326" quat="0.999125 0.00256393 -0.0409531 0.00806091" mass="1.013" diaginertia="0.00555739 0.00513936 0.00133944" />
                    <joint name="RL_thigh_joint" pos="0 0 0" axis="0 1 0" limited="true" range="-1.0472 4.18879" />
                    <geom type="mesh" contype="0" conaffinity="0" group="1" rgba="1 0.423529 0.0392157 1" mesh="thigh" />
                    <geom size="0.1 0.01225 0.017" pos="0 0 -0.1" quat="0.707107 0 0.707107 0" type="box" rgba="1 0.423529 0.0392157 0" />
                    <body name="RL_calf" pos="0 0 -0.2">
                        <inertial pos="0.00472659 0 -0.131975" quat="0.706886 0.017653 0.017653 0.706886" mass="0.226" diaginertia="0.00340344 0.00339393 3.54834e-05" />
                        <joint name="RL_calf_joint" pos="0 0 0" axis="0 1 0" limited="true" range="-2.69653 -0.916298" />
                        <geom type="mesh" contype="0" conaffinity="0" group="1" rgba="1 0.423529 0.0392157 1" mesh="calf" />
                        <geom size="0.1 0.008 0.008" pos="0 0 -0.1" quat="0.707107 0 0.707107 0" type="box" rgba="1 0.423529 0.0392157 0" />
                        <geom size="0.01" pos="0 0 -0.2" contype="0" conaffinity="0" group="1" rgba="1 0.423529 0.0392157 0" />
                        <geom size="0.02" pos="0 0 -0.2" rgba="1 0.423529 0.0392157 0" />
                    </body>
                </body>
            </body>
        </body>
    </worldbody>

    <actuator>
        <general name="RR_hip_motor" ctrllimited="true" ctrlrange="-20 20" joint="RR_hip_joint"
                 gainprm="0.0578" gear="47.2660957561"/>
        <general name="RR_thigh_motor" ctrllimited="true" ctrlrange="-20 20" joint="RR_thigh_joint"
                 gainprm="0.0578" gear="47.2660957561"/>
        <general name="RR_calf_motor" ctrllimited="true" ctrlrange="-20 20" joint="RR_calf_joint"
                 gainprm="0.0578" gear="47.2660957561"/>

        <general name="RL_hip_motor" ctrllimited="true" ctrlrange="-20 20" joint="RL_hip_joint"
                 gainprm="0.0578" gear="47.2660957561"/>
        <general name="RL_thigh_motor" ctrllimited="true" ctrlrange="-20 20" joint="RL_thigh_joint"
                 gainprm="0.0578" gear="47.2660957561"/>
        <general name="RL_calf_motor" ctrllimited="true" ctrlrange="-20 20" joint="RL_calf_joint"
                 gainprm="0.0578" gear="47.2660957561"/>

        <general name="FL_hip_motor" ctrllimited="true" ctrlrange="-20 20" joint="FL_hip_joint"
                 gainprm="0.0578" gear="47.2660957561"/>
        <general name="FL_thigh_motor" ctrllimited="true" ctrlrange="-20 20" joint="FL_thigh_joint"
                 gainprm="0.0578" gear="47.2660957561"/>
        <general name="FL_calf_motor" ctrllimited="true" ctrlrange="-20 20" joint="FL_calf_joint"
                 gainprm="0.0578" gear="47.2660957561"/>

        <general name="FR_hip_motor" ctrllimited="true" ctrlrange="-20 20" joint="FR_hip_joint"
                 gainprm="0.0578" gear="47.2660957561"/>
        <general name="FR_thigh_motor" ctrllimited="true" ctrlrange="-20 20" joint="FR_thigh_joint"
                 gainprm="0.0578" gear="47.2660957561"/>
        <general name="FR_calf_motor" ctrllimited="true" ctrlrange="-20 20" joint="FR_calf_joint"
                 gainprm="0.0578" gear="47.2660957561"/>
    </actuator>
</mujoco>
